<p>The difference becomes obvious when we look at the code inside a function.</p>
<p>The behavior is different if there’s a “jump out” of <code>try..catch</code>.</p>
<p>For instance, when there’s a <code>return</code> inside <code>try..catch</code>. The <code>finally</code> clause works in case of <em>any</em> exit from <code>try..catch</code>, even via the <code>return</code> statement: right after <code>try..catch</code> is done, but before the calling code gets the control.</p>
<p>```js run function f() { try { alert(‘start’); <em>!</em> return “result”; <em>/!</em> } catch (e) { /// … } finally { alert(‘cleanup!’); } }</p>
<p>f(); // cleanup! ```</p>
<p>…Or when there’s a <code>throw</code>, like here:</p>
<p>```js run function f() { try { alert(‘start’); throw new Error(“an error”); } catch (e) { // … if(“can’t handle the error”) { <em>!</em> throw e; <em>/!</em> }</p>
<p>} finally { alert(‘cleanup!’) } }</p>
<p>f(); // cleanup! ```</p>
<p>It’s <code>finally</code> that guarantees the cleanup here. If we just put the code at the end of <code>f</code>, it wouldn’t run in these situations.</p>
